Workbook

Sheet Grade
B1: SENG1050 Web-Based Assignment 1 Rubrics
B3: Name and ID | C3: {=_xlfn.TEXTAFTER(_xlfn.TEXTBEFORE(CELL("filename"),".xlsx"),"[")} -> SENG1050-Assessment-02-Rubrics-2025-S2
D5: Status | E5: Multiplier | F5: Student Mark | G5: Comments
B6: General Requirements | C6: =SUM(C7) -> 2 | F6: =SUM(F7) -> 0
A7: 1 | B7: Proper directory setup. | C7: =SUM(C8:C9) -> 2 | F7: =SUM(F8:F9) -> 0
B8: fevergamez as root directory. | C8: 1 | E8: =VLOOKUP(D8,Raw!$A$2:$B$23,2,FALSE) -> 0 | F8: =C8*E8 -> 0
B9: fevergamez/image as image directory. | C9: 1 | E9: =VLOOKUP(D9,Raw!$A$2:$B$23,2,FALSE) -> 0 | F9: =C9*E9 -> 0
B11: HTML Documents | C11: =SUM(C12,C17,C30,C38) -> 47 | F11: =SUM(F12,F17,F30,F38) -> 0
A12: 1 | B12: All web pages. | C12: =SUM(C13:C16) -> 8 | F12: =SUM(F13:F16) -> 0
B13: Full HTML document structure (include <!DOCTYPE>, <html>, <head>, <meta>, <title>, and <body>). | C13: 3 | E13: =VLOOKUP(D13,Raw!$A$2:$B$23,2,FALSE) -> 0 | F13: =C13*E13 -> 0
B14: Navigation bar: Uses hyperlinks to link all pages to one another. | C14: 2 | E14: =VLOOKUP(D14,Raw!$A$2:$B$23,2,FALSE) -> 0 | F14: =C14*E14 -> 0
B15: Navigation bar: Hyperlinks implemented using relative URLs. | C15: 1.5 | E15: =VLOOKUP(D15,Raw!$A$2:$B$23,2,FALSE) -> 0 | F15: =C15*E15 -> 0
B16: Copyright statement in proper HTML structuring element for the homepage (<address>). | C16: 1.5 | E16: =VLOOKUP(D16,Raw!$A$2:$B$23,2,FALSE) -> 0 | F16: =C16*E16 -> 0
A17: 2 | B17: Homepage. | C17: =SUM(C18:C29) -> 18.5 | F17: =SUM(F18:F29) -> 0
B18: Correct file name. | C18: 0.5 | E18: =VLOOKUP(D18,Raw!$A$2:$B$23,2,FALSE) -> 0 | F18: =C18*E18 -> 0
B19: Welcome note: Proper and meaningful level 1 heading. | C19: 1 | E19: =VLOOKUP(D19,Raw!$A$2:$B$23,2,FALSE) -> 0 | F19: =C19*E19 -> 0
B20: Welcome note: One to two meaningful paragraphs of welcome note. | C20: 1 | E20: =VLOOKUP(D20,Raw!$A$2:$B$23,2,FALSE) -> 0 | F20: =C20*E20 -> 0
B21: Welcome note: One meaningful blockquote. | C21: 1 | E21: =VLOOKUP(D21,Raw!$A$2:$B$23,2,FALSE) -> 0 | F21: =C21*E21 -> 0
B22: Feature product section: Proper and meaningful level 1 and 2 headings. | C22: 2 | E22: =VLOOKUP(D22,Raw!$A$2:$B$23,2,FALSE) -> 0 | F22: =C22*E22 -> 0
B23: Feature product section: An unordered list or an ordered list of THREE feature products (regardless of genre). | C23: 3 | E23: =VLOOKUP(D23,Raw!$A$2:$B$23,2,FALSE) -> 0 | F23: =C23*E23 -> 0
B24: Feature product section: One short description paragraph for each product. | C24: 3 | E24: =VLOOKUP(D24,Raw!$A$2:$B$23,2,FALSE) -> 0 | F24: =C24*E24 -> 0
B25: Feature product section: One image for each product. | C25: 3 | E25: =VLOOKUP(D25,Raw!$A$2:$B$23,2,FALSE) -> 0 | F25: =C25*E25 -> 0
B26: One hyperlink to an external website using an absolute URL. | C26: 1 | E26: =VLOOKUP(D26,Raw!$A$2:$B$23,2,FALSE) -> 0 | F26: =C26*E26 -> 0
B27: Correct utilization of EM tag. | C27: 1 | E27: =VLOOKUP(D27,Raw!$A$2:$B$23,2,FALSE) -> 0 | F27: =C27*E27 -> 0
B28: Correct utilization of STRONG tag. | C28: 1 | E28: =VLOOKUP(D28,Raw!$A$2:$B$23,2,FALSE) -> 0 | F28: =C28*E28 -> 0
B29: Correct utilization of ABBR tag. | C29: 1 | E29: =VLOOKUP(D29,Raw!$A$2:$B$23,2,FALSE) -> 0 | F29: =C29*E29 -> 0
A30: 3 | B30: About Us page. | C30: =SUM(C31:C37) -> 10.5 | F30: =SUM(F31:F37) -> 0
B31: Correct file name. | C31: 0.5 | E31: =VLOOKUP(D31,Raw!$A$2:$B$23,2,FALSE) -> 0 | F31: =C31*E31 -> 0
B32: History section: Proper and meaningful level 1 heading. | C32: 1 | E32: =VLOOKUP(D32,Raw!$A$2:$B$23,2,FALSE) -> 0 | F32: =C32*E32 -> 0
B33: History section: One to two meaningful paragraphs of history. | C33: 1 | E33: =VLOOKUP(D33,Raw!$A$2:$B$23,2,FALSE) -> 0 | F33: =C33*E33 -> 0
B34: Privacy policy section: Proper and meaningful level 1 and 2 headings. | C34: 2 | E34: =VLOOKUP(D34,Raw!$A$2:$B$23,2,FALSE) -> 0 | F34: =C34*E34 -> 0
B35: Privacy policy section: Paragraphs of discussion on privacy policy. | C35: 2 | E35: =VLOOKUP(D35,Raw!$A$2:$B$23,2,FALSE) -> 0 | F35: =C35*E35 -> 0
B36: Terms and conditions section: Proper and meaningful level 1 and 2 headings. | C36: 2 | E36: =VLOOKUP(D36,Raw!$A$2:$B$23,2,FALSE) -> 0 | F36: =C36*E36 -> 0
B37: Terms and conditions section: Paragraphs of discussion on terms and conditions . | C37: 2 | E37: =VLOOKUP(D37,Raw!$A$2:$B$23,2,FALSE) -> 0 | F37: =C37*E37 -> 0
A38: 4 | B38: Contact page. | C38: =SUM(C39:C48) -> 10 | F38: =SUM(F39:F48) -> 0
B39: Correct file name. | C39: 0.5 | E39: =VLOOKUP(D39,Raw!$A$2:$B$23,2,FALSE) -> 0 | F39: =C39*E39 -> 0
B40: Appropriate level 2 heading. | C40: 1 | E40: =VLOOKUP(D40,Raw!$A$2:$B$23,2,FALSE) -> 0 | F40: =C40*E40 -> 0
B41: Name of the person sending a message. | C41: 1 | E41: =VLOOKUP(D41,Raw!$A$2:$B$23,2,FALSE) -> 0 | F41: =C41*E41 -> 0
B42: An email address for replies. | C42: 1 | E42: =VLOOKUP(D42,Raw!$A$2:$B$23,2,FALSE) -> 0 | F42: =C42*E42 -> 0
B43: The subject of the message. | C43: 1 | E43: =VLOOKUP(D43,Raw!$A$2:$B$23,2,FALSE) -> 0 | F43: =C43*E43 -> 0
...

Sheet Raw
A1: Status | B1: Multiplier
B2: 0
A3: Fulfilled | B3: 1
A4: Partially Fulfilled | B4: 0.5
A5: Not Fulfilled | B5: 0
A6: 0.95 | B6: =A6 -> 0.95
A7: 0.9 | B7: =A7 -> 0.9
A8: 0.85 | B8: =A8 -> 0.85
A9: 0.8 | B9: =A9 -> 0.8
A10: 0.75 | B10: =A10 -> 0.75
A11: 0.7 | B11: =A11 -> 0.7
A12: 0.65 | B12: =A12 -> 0.65
A13: 0.6 | B13: =A13 -> 0.6
A14: 0.55 | B14: =A14 -> 0.55
A15: 0.45 | B15: =A15 -> 0.45
A16: 0.4 | B16: =A16 -> 0.4
A17: 0.35 | B17: =A17 -> 0.35
... A23: 0.05 | B23: =A23 -> 0.05
